#VRML_SIM R2022b utf8

EXTERNPROTO "https://raw.githubusercontent.com/cyberbotics/webots/R2022b/projects/objects/backgrounds/protos/TexturedBackground.proto"
EXTERNPROTO "https://raw.githubusercontent.com/cyberbotics/webots/R2022b/projects/objects/backgrounds/protos/TexturedBackgroundLight.proto"
EXTERNPROTO "https://raw.githubusercontent.com/cyberbotics/webots/R2022b/projects/objects/factory/containers/protos/WoodenBox.proto"
EXTERNPROTO "https://raw.githubusercontent.com/cyberbotics/webots/R2022b/projects/objects/floors/protos/Floor.proto"
EXTERNPROTO "../protos/FourWheelsRobot.proto"

WorldInfo {
  contactProperties [
    ContactProperties {
      material2 "db"
      coulombFriction [
        0.5
      ]
    }
  ]
}
Viewpoint {
  orientation 0.24382463790974718 0.005927614798041886 -0.9698012215557303 3.0653931449865253
  position 0.9706737476896006 0.01701538335907322 0.6295444339751886
}
TexturedBackground {
}
TexturedBackgroundLight {
}
WoodenBox {
  translation 0.26363 0.0027135 0.05
  rotation 0 1 0 0
  size 0.1 0.1 0.1
}
Floor {
  size 1 1
  tileSize 0.25 0.25
}
DEF Wall_ Solid {
  translation 0 0.5 0.05
  children [
    DEF Wall_Shape Shape {
      appearance PBRAppearance {
        baseColor 0.666667 1 0
        baseColorMap ImageTexture {
          url [
            "../red_brick_wall.jpg"
          ]
        }
        roughness 0.5
        metalness 0
      }
      geometry DEF Box Box {
        size 1 0.05 0.1
      }
    }
  ]
  name "solid(2)"
  boundingObject USE Box
}
DEF Wall Solid {
  translation 0 -0.5 0.05
  children [
    USE Wall_Shape
  ]
  name "solid(3)"
  boundingObject USE Box
}
DEF Wall Solid {
  translation -0.473 0 0.05
  rotation 0 0 1 1.57733
  children [
    USE Wall_Shape
  ]
  name "solid(4)"
  boundingObject USE Box
}
DEF Wall Solid {
  translation 0.473 0 0.05
  rotation 0 0 1 1.57733
  children [
    USE Wall_Shape
  ]
  name "solid(5)"
  boundingObject USE Box
}
Robot {
  translation -0.000118012 -0.270022 0.0385184
  rotation 0.6348187944074064 -0.7724441844369752 0.018305195891422262 0.005626544895770979
  children [
    DEF Body Shape {
      appearance PBRAppearance {
        baseColor 1 1 0
        metalness 0
      }
      geometry Box {
        size 0.2 0.1 0.05
      }
    }
    HingeJoint {
      jointParameters HingeJointParameters {
        position -2.4859225788986805e-09
        axis 0 1 0
        anchor 0.05 0.06 0
      }
      device [
        RotationalMotor {
          name "Wheel1"
        }
      ]
      endPoint Solid {
        translation 0.05 0.06 0
        rotation 1 -7.247328445245603e-11 2.4150639321630422e-09 1.5700000016541684
        children [
          DEF Wheel Shape {
            appearance PBRAppearance {
              baseColor 0.666667 0.333333 0
              metalness 0
            }
            geometry Cylinder {
              height 0.02
              radius 0.04
            }
          }
        ]
        boundingObject USE Wheel
        physics DEF Physics_wh Physics {
        }
      }
    }
    HingeJoint {
      jointParameters HingeJointParameters {
        position 4.299235748080734e-07
        axis 0 1 0
        anchor 0.05 -0.06 0
      }
      device [
        RotationalMotor {
          name "Wheel2"
        }
      ]
      endPoint Solid {
        translation 0.05000010416983096 -0.059999917329054436 8.563425039058427e-06
        rotation 1 5.856207332538482e-09 4.503843962622937e-09 1.5699996025854566
        children [
          USE Wheel
        ]
        name "solid(1)"
        boundingObject USE Wheel
        physics USE Physics_wh
      }
    }
    HingeJoint {
      jointParameters HingeJointParameters {
        position -4.290171782272978e-07
        axis 0 1 0
        anchor -0.05 0.06 0
      }
      device [
        RotationalMotor {
          name "Wheel3"
        }
      ]
      endPoint Solid {
        translation -0.049999879878117465 0.06000011167753841 8.682611932767563e-06
        rotation 1 -6.586575456614444e-09 -6.119531605385731e-09 1.5700004134164582
        children [
          USE Wheel
        ]
        name "solid(2)"
        boundingObject USE Wheel
        physics USE Physics_wh
      }
    }
    HingeJoint {
      jointParameters HingeJointParameters {
        position 2.754153233738781e-14
        axis 0 1 0
        anchor -0.05 -0.06 0
      }
      device [
        RotationalMotor {
          name "Wheel4"
        }
      ]
      endPoint Solid {
        translation -0.049999999999999906 -0.059999999999999935 -1.651633240743511e-15
        rotation 0.9999999999999999 8.276895530349983e-14 -8.264423098698324e-14 1.570000000000081
        children [
          USE Wheel
        ]
        name "solid(3)"
        boundingObject USE Wheel
        physics USE Physics_wh
      }
    }
    DistanceSensor {
      translation 0.1 0.02 0
      rotation 0 0 1 0.3
      children [
        DEF sensor Shape {
          appearance PBRAppearance {
            baseColor 0.333333 1 1
            metalness 0
          }
          geometry Box {
            size 0.01 0.01 0.01
          }
        }
      ]
      name "ds_left"
      boundingObject USE sensor
      physics Physics {
      }
    }
    DistanceSensor {
      translation 0.1 -0.02 0
      rotation 0 0 1 -0.27
      children [
        DEF sensor Shape {
          appearance PBRAppearance {
            baseColor 0.333333 1 1
            metalness 0
          }
          geometry Box {
            size 0.01 0.01 0.01
          }
        }
      ]
      name "ds_right"
      boundingObject USE sensor
      physics Physics {
      }
    }
  ]
  boundingObject USE Body
  physics Physics {
    density -1
    mass 1
  }
  controller "four_wheeled_collision_avoidance"
}
FourWheelsRobot {
}
