#VRML_SIM R2022b utf8

EXTERNPROTO "https://raw.githubusercontent.com/cyberbotics/webots/R2022b/projects/objects/backgrounds/protos/TexturedBackground.proto"
EXTERNPROTO "https://raw.githubusercontent.com/cyberbotics/webots/R2022b/projects/objects/backgrounds/protos/TexturedBackgroundLight.proto"
EXTERNPROTO "https://raw.githubusercontent.com/cyberbotics/webots/R2022b/projects/objects/factory/containers/protos/WoodenBox.proto"
EXTERNPROTO "https://raw.githubusercontent.com/cyberbotics/webots/R2022b/projects/objects/floors/protos/Floor.proto"

WorldInfo {
  contactProperties [
    ContactProperties {
      material2 "db"
      coulombFriction [
        0.5
      ]
    }
  ]
}
Viewpoint {
  orientation 0.509163967146666 0.1524531791874812 -0.8470596689225018 2.5638701376727457
  position 1.8495466708307595 1.8915752787686568 4.588146299365094
}
TexturedBackground {
}
TexturedBackgroundLight {
}
WoodenBox {
  translation -0.28022 0.407457 0.0496074
  rotation -9.514084088835292e-07 -3.0566587232861127e-07 -0.9999999999995007 1.436014554826855
  size 0.1 0.1 0.1
  mass 1
}
WoodenBox {
  translation 0.187115 0.466296 0.0496074
  rotation -9.514084088835292e-07 -3.0566587232861127e-07 -0.9999999999995007 1.436014554826855
  name "wooden box(1)"
  size 0.1 0.1 0.1
  mass 1
}
WoodenBox {
  translation -0.429651 -0.015128 0.0496074
  rotation -9.514084088835292e-07 -3.0566587232861127e-07 -0.9999999999995007 1.436014554826855
  name "wooden box(2)"
  size 0.1 0.1 0.1
  mass 1
}
WoodenBox {
  translation -0.760341 -0.567252 0.0496074
  rotation -9.514084088835292e-07 -3.0566587232861127e-07 -0.9999999999995007 1.436014554826855
  name "wooden box(3)"
  size 0.1 0.1 0.1
  mass 1
}
WoodenBox {
  translation 0.489666 -0.300937 0.0496074
  rotation -9.514084088835292e-07 -3.0566587232861127e-07 -0.9999999999995007 1.436014554826855
  name "wooden box(4)"
  size 0.1 0.1 0.1
  mass 1
}
WoodenBox {
  translation 0.075355 -0.443688 0.0496074
  rotation -9.514084088835292e-07 -3.0566587232861127e-07 -0.9999999999995007 1.436014554826855
  name "wooden box(5)"
  size 0.1 0.1 0.1
  mass 1
}
WoodenBox {
  translation -0.380386 -0.52386 0.0496074
  rotation -9.514084088835292e-07 -3.0566587232861127e-07 -0.9999999999995007 1.436014554826855
  name "wooden box(6)"
  size 0.1 0.1 0.1
  mass 1
}
WoodenBox {
  translation -0.0896525 0.722812 0.0496074
  rotation -9.514084088835292e-07 -3.0566587232861127e-07 -0.9999999999995007 1.436014554826855
  name "wooden box(7)"
  size 0.1 0.1 0.1
  mass 1
}
WoodenBox {
  translation 0.670848 0.216189 0.0496074
  rotation -9.514084088835292e-07 -3.0566587232861127e-07 -0.9999999999995007 1.436014554826855
  name "wooden box(8)"
  size 0.1 0.1 0.1
  mass 1
}
Floor {
  size 2 2
  tileSize 0.25 0.25
}
Robot {
  translation 0.32156620071550435 0.05738579593544365 0.03972175943815029
  rotation 3.0076069575108222e-05 -0.00010430935944207724 0.9999999941074936 1.8878685642625517
  children [
    DEF Body Shape {
      appearance PBRAppearance {
        baseColor 1 1 0
        metalness 0
      }
      geometry Box {
        size 0.2 0.1 0.05
      }
    }
    HingeJoint {
      jointParameters HingeJointParameters {
        position 226.56577167661953
        axis 0 1 0
        anchor 0.05 0.06 0
      }
      device [
        RotationalMotor {
          name "Wheel1"
        }
      ]
      endPoint Solid {
        translation 0.04999863950467152 0.06000000009977072 3.7578882715447938e-06
        rotation -0.9664990215175695 -0.18156555843827826 0.1814210279834636 4.679116452363829
        children [
          DEF Wheel Shape {
            appearance PBRAppearance {
              baseColor 0.666667 0.333333 0
              metalness 0
            }
            geometry Cylinder {
              height 0.02
              radius 0.04
            }
          }
        ]
        boundingObject USE Wheel
        physics DEF Physics_wh Physics {
        }
      }
    }
    HingeJoint {
      jointParameters HingeJointParameters {
        position 159.81718787489226
        axis 0 1 0
        anchor 0.05 -0.06 0
      }
      device [
        RotationalMotor {
          name "Wheel2"
        }
      ]
      endPoint Solid {
        translation 0.05000399900077527 -0.05999991723334277 -1.1736639982322275e-05
        rotation 0.14327328662691918 0.7000903997549373 -0.699532842338437 2.8567591722453756
        children [
          USE Wheel
        ]
        name "solid(1)"
        boundingObject USE Wheel
        physics USE Physics_wh
      }
    }
    HingeJoint {
      jointParameters HingeJointParameters {
        position 227.38943670263964
        axis 0 1 0
        anchor -0.05 0.06 0
      }
      device [
        RotationalMotor {
          name "Wheel3"
        }
      ]
      endPoint Solid {
        translation -0.04999012850648013 0.06000011177327655 6.471607832933289e-06
        rotation -0.7204957784915744 -0.4905448846596092 0.490154617758632 4.391046718110267
        children [
          USE Wheel
        ]
        name "solid(2)"
        boundingObject USE Wheel
        physics USE Physics_wh
      }
    }
    HingeJoint {
      jointParameters HingeJointParameters {
        position 159.96510179385822
        axis 0 1 0
        anchor -0.05 -0.06 0
      }
      device [
        RotationalMotor {
          name "Wheel4"
        }
      ]
      endPoint Solid {
        translation -0.04999983833342035 -0.05999999990128034 -4.001451620430415e-06
        rotation 0.09064072258297683 0.7044764163459719 -0.703915647092727 2.9606619900348066
        children [
          USE Wheel
        ]
        name "solid(3)"
        boundingObject USE Wheel
        physics USE Physics_wh
      }
    }
    DistanceSensor {
      translation 0.1 0.02 0
      rotation 0 0 1 0.3
      children [
        DEF sensor Shape {
          appearance PBRAppearance {
            baseColor 0.333333 1 1
            metalness 0
          }
          geometry Box {
            size 0.01 0.01 0.01
          }
        }
      ]
      name "ds_left"
      boundingObject USE sensor
      physics Physics {
      }
    }
    DistanceSensor {
      translation 0.1 -0.02 0
      rotation 0 0 1 -0.27
      children [
        DEF sensor Shape {
          appearance PBRAppearance {
            baseColor 0.333333 1 1
            metalness 0
          }
          geometry Box {
            size 0.01 0.01 0.01
          }
        }
      ]
      name "ds_right"
      boundingObject USE sensor
      physics Physics {
      }
    }
    DistanceSensor {
      translation 0.085 0 -0.023
      rotation -0.004100340762836766 -0.9999831860391573 0.004100590762883277 -1.5708153071795863
      children [
        DEF colorSensor Shape {
          appearance PBRAppearance {
            baseColor 0.333333 1 1
            metalness 0
          }
          geometry Box {
            size 0.01 0.01 0.01
          }
        }
      ]
      name "colorSensor"
      boundingObject USE colorSensor
      physics Physics {
      }
      type "infra-red"
    }
  ]
  boundingObject USE Body
  physics Physics {
    density -1
    mass 1
  }
  controller "four_wheeled_collision_avoidance"
}
