#VRML_SIM R2022b utf8

EXTERNPROTO "https://raw.githubusercontent.com/cyberbotics/webots/R2022b/projects/objects/backgrounds/protos/TexturedBackground.proto"
EXTERNPROTO "https://raw.githubusercontent.com/cyberbotics/webots/R2022b/projects/objects/backgrounds/protos/TexturedBackgroundLight.proto"
EXTERNPROTO "https://raw.githubusercontent.com/cyberbotics/webots/R2022b/projects/objects/factory/containers/protos/WoodenBox.proto"
EXTERNPROTO "https://raw.githubusercontent.com/cyberbotics/webots/R2022b/projects/objects/floors/protos/Floor.proto"

WorldInfo {
  contactProperties [
    ContactProperties {
      material2 "db"
      coulombFriction [
        0.5
      ]
    }
  ]
}
Viewpoint {
  orientation 0.404853174655869 0.5318820126626488 -0.7437710881561574 1.4875486918122818
  position -0.7126416357287385 2.3041629153709526 2.9770266573258
}
TexturedBackground {
}
TexturedBackgroundLight {
}
WoodenBox {
  translation -0.2802200260311171 0.40745693963693325 0.04960759998325078
  rotation -8.56565651906031e-11 -2.7519436206208488e-11 -0.9999999999999999 1.4360145548263612
  size 0.1 0.1 0.1
  mass 1
}
WoodenBox {
  translation 0.18711497396888285 0.46629593963693317 0.04960759998325079
  rotation -8.56565420796837e-11 -2.751950206326519e-11 -1 1.4360145548263612
  name "wooden box(1)"
  size 0.1 0.1 0.1
  mass 1
}
WoodenBox {
  translation -0.735755 0.00110829 0.0496076
  rotation -8.56564914813762e-11 -2.751950088558743e-11 -1 1.436014554826361
  name "wooden box(2)"
  size 0.1 0.1 0.1
  mass 0.3
}
WoodenBox {
  translation 0.685703 -0.684544 0.0496076
  rotation -8.565642203441289e-11 -2.7519560684378194e-11 -1 1.436014554826361
  name "wooden box(3)"
  size 0.1 0.1 0.1
  mass 1
}
WoodenBox {
  translation 0.4599399977282467 -0.29029400526792637 0.049607600000000016
  rotation -8.565640071854098e-11 -2.7519585086527592e-11 -0.9999999999999999 1.4360145548263612
  name "wooden box(4)"
  size 0.1 0.1 0.1
  mass 1
}
WoodenBox {
  translation 0.07535497396888288 -0.44368806036306685 0.04960759998325079
  rotation -8.56564993335835e-11 -2.7519413095173355e-11 -1 1.4360145548263612
  name "wooden box(5)"
  size 0.1 0.1 0.1
  mass 1
}
WoodenBox {
  translation -0.38038602603116384 -0.5238600603631745 0.04980360690824043
  rotation -8.39596909674059e-11 -2.6974376432005448e-11 -0.9999999999999999 1.4360145548263612
  name "wooden box(6)"
  size 0.1 0.1 0.1
  mass 0.5
}
WoodenBox {
  translation -0.05315380227175347 0.6985859947320738 0.0496076
  rotation -8.565642629791808e-11 -2.7519555804220403e-11 -0.9999999999999999 1.4360145548263612
  name "wooden box(7)"
  size 0.1 0.1 0.1
  mass 1
}
WoodenBox {
  translation 0.670847973968883 0.21618893963693317 0.04960759998325077
  rotation -8.565647745658392e-11 -2.7519497239360387e-11 -1 1.436014554826361
  name "wooden box(8)"
  size 0.1 0.1 0.1
  mass 1
}
Floor {
  size 2 2
  tileSize 0.25 0.25
}
Robot {
  translation 0.28585423616044225 0.17877404164901395 0.039727450271653704
  rotation -3.798676020051895e-05 -1.0454658274744102e-05 0.9999999992238531 1.994080653497808
  children [
    DEF Body Shape {
      appearance PBRAppearance {
        baseColor 1 1 0
        metalness 0
      }
      geometry Box {
        size 0.2 0.1 0.05
      }
    }
    HingeJoint {
      jointParameters HingeJointParameters {
        position 233.77101144516163
        axis 0 1 0
        anchor 0.05 0.06 0
      }
      device [
        RotationalMotor {
          name "Wheel1"
        }
      ]
      endPoint Solid {
        translation 0.0500021724628988 0.06000000009977072 3.354560590246969e-06
        rotation 0.6835206564722944 0.5163447469935876 -0.5159337306552187 1.941690245845716
        children [
          DEF Wheel Shape {
            appearance PBRAppearance {
              baseColor 0.666667 0.333333 0
              metalness 0
            }
            geometry Cylinder {
              height 0.02
              radius 0.04
            }
          }
        ]
        boundingObject USE Wheel
        physics DEF Physics_wh Physics {
        }
      }
    }
    HingeJoint {
      jointParameters HingeJointParameters {
        position 159.01195043561478
        axis 0 1 0
        anchor 0.05 -0.06 0
      }
      device [
        RotationalMotor {
          name "Wheel2"
        }
      ]
      endPoint Solid {
        translation 0.050011233128872006 -0.05999991723334277 -5.249527694964187e-06
        rotation 0.4388502150576769 0.6356310945503711 -0.6351248699149862 2.3139197989390072
        children [
          USE Wheel
        ]
        name "solid(1)"
        boundingObject USE Wheel
        physics USE Physics_wh
      }
    }
    HingeJoint {
      jointParameters HingeJointParameters {
        position 234.59467383886695
        axis 0 1 0
        anchor -0.05 0.06 0
      }
      device [
        RotationalMotor {
          name "Wheel3"
        }
      ]
      endPoint Solid {
        translation -0.049988878922137346 0.06000011177327655 -3.955972627420195e-06
        rotation 0.3694571185598849 0.6573388408241182 -0.6568158690907457 2.433270357782294
        children [
          USE Wheel
        ]
        name "solid(2)"
        boundingObject USE Wheel
        physics USE Physics_wh
      }
    }
    HingeJoint {
      jointParameters HingeJointParameters {
        position 159.1598621819523
        axis 0 1 0
        anchor -0.05 -0.06 0
      }
      device [
        RotationalMotor {
          name "Wheel4"
        }
      ]
      endPoint Solid {
        translation -0.04999700294158996 -0.05999999990128034 -2.656198795330995e-06
        rotation 0.3831365190343224 0.6534086920057747 -0.6528885731834835 2.4092905894080188
        children [
          USE Wheel
        ]
        name "solid(3)"
        boundingObject USE Wheel
        physics USE Physics_wh
      }
    }
    DistanceSensor {
      translation 0.1 0.02 0
      rotation 0 0 -1 -0.038205307179586256
      children [
        DEF sensor Shape {
          appearance PBRAppearance {
            baseColor 0.333333 1 1
            metalness 0
          }
          geometry Box {
            size 0.01 0.01 0.01
          }
        }
      ]
      name "ds_left"
      boundingObject USE sensor
      physics Physics {
      }
      lookupTable [
        0 0 0
        0.6 1000 0
      ]
      aperture 1.57
    }
    DistanceSensor {
      translation 0.1 -0.02 0
      rotation 0 0 -1 0.00820061
      children [
        DEF sensor Shape {
          appearance PBRAppearance {
            baseColor 0.333333 1 1
            metalness 0
          }
          geometry Box {
            size 0.01 0.01 0.01
          }
        }
      ]
      name "ds_right"
      boundingObject USE sensor
      physics Physics {
      }
      lookupTable [
        0 0 0
        0.6 1000 0
      ]
    }
    DistanceSensor {
      translation 0.085 0 -0.023
      rotation -0.004100340762836766 -0.9999831860391573 0.004100590762883277 -1.5708153071795863
      children [
        DEF colorSensor Shape {
          appearance PBRAppearance {
            baseColor 0.333333 1 1
            metalness 0
          }
          geometry Box {
            size 0.01 0.01 0.01
          }
        }
      ]
      name "colorSensor"
      boundingObject USE colorSensor
      physics Physics {
      }
      type "infra-red"
    }
  ]
  boundingObject USE Body
  physics Physics {
    density -1
    mass 1
  }
  controller "four_wheeled_collision_avoidance"
}
