#VRML_SIM R2022b utf8

EXTERNPROTO "https://raw.githubusercontent.com/cyberbotics/webots/R2022b/projects/objects/backgrounds/protos/TexturedBackground.proto"
EXTERNPROTO "https://raw.githubusercontent.com/cyberbotics/webots/R2022b/projects/objects/backgrounds/protos/TexturedBackgroundLight.proto"
EXTERNPROTO "https://raw.githubusercontent.com/cyberbotics/webots/R2022b/projects/objects/factory/containers/protos/WoodenBox.proto"
EXTERNPROTO "https://raw.githubusercontent.com/cyberbotics/webots/R2022b/projects/objects/floors/protos/Floor.proto"

WorldInfo {
  contactProperties [
    ContactProperties {
      material2 "db"
      coulombFriction [
        0.5
      ]
    }
  ]
}
Viewpoint {
  orientation 0.509163967146666 0.1524531791874812 -0.8470596689225018 2.5638701376727457
  position 1.8495466708307595 1.8915752787686568 4.588146299365094
}
TexturedBackground {
}
TexturedBackgroundLight {
}
WoodenBox {
  translation -0.2802200237593637 0.40745694490485956 0.04960758287056527
  rotation -8.310810693586232e-08 -2.6700743698089376e-08 -0.9999999999999963 1.4360145548263648
  size 0.1 0.1 0.1
  mass 1
}
WoodenBox {
  translation 0.18711497624063636 0.46629594490485954 0.04960758287056527
  rotation -8.310810700351406e-08 -2.6700743679745505e-08 -0.9999999999999963 1.4360145548263648
  name "wooden box(1)"
  size 0.1 0.1 0.1
  mass 1
}
WoodenBox {
  translation -0.4296510237593637 -0.015128055095140496 0.04960758287056528
  rotation -8.310810704367824e-08 -2.670074359436689e-08 -0.9999999999999963 1.4360145548263648
  name "wooden box(2)"
  size 0.1 0.1 0.1
  mass 1
}
WoodenBox {
  translation -0.7603410237593637 -0.5672520550951403 0.04960758287056527
  rotation -8.31081069492123e-08 -2.6700743623705808e-08 -0.9999999999999961 1.4360145548263648
  name "wooden box(3)"
  size 0.1 0.1 0.1
  mass 1
}
WoodenBox {
  translation 0.45994 -0.290294 0.0496076
  rotation -8.310810698264502e-08 -2.6700743506633315e-08 -0.9999999999999963 1.4360145548263648
  name "wooden box(4)"
  size 0.1 0.1 0.1
  mass 1
}
WoodenBox {
  translation 0.07535497624063638 -0.4436880550951405 0.04960758287056526
  rotation -8.310810700351387e-08 -2.6700743679745313e-08 -0.9999999999999963 1.4360145548263648
  name "wooden box(5)"
  size 0.1 0.1 0.1
  mass 1
}
WoodenBox {
  translation -0.3803860237593637 -0.5238600550951404 0.04960758287056526
  rotation -8.310810693025157e-08 -2.670074354691067e-08 -0.9999999999999963 1.4360145548263648
  name "wooden box(6)"
  size 0.1 0.1 0.1
  mass 1
}
WoodenBox {
  translation -0.08965252375936363 0.7228119449048597 0.04960758287056527
  rotation -8.310810699498744e-08 -2.6700743689506295e-08 -0.9999999999999961 1.4360145548263648
  name "wooden box(7)"
  size 0.1 0.1 0.1
  mass 1
}
WoodenBox {
  translation 0.6708479762406364 0.2161889449048595 0.04960758287056527
  rotation -8.310810691992975e-08 -2.6700743598126313e-08 -0.9999999999999961 1.4360145548263648
  name "wooden box(8)"
  size 0.1 0.1 0.1
  mass 1
}
Floor {
  size 2 2
  tileSize 0.25 0.25
}
Robot {
  translation 0.2856531658708959 0.1647776311057121 0.039721067568226215
  rotation 0.0001238571487970653 3.1239083416229033e-06 0.9999999923248241 1.8878711334791802
  children [
    DEF Body Shape {
      appearance PBRAppearance {
        baseColor 1 1 0
        metalness 0
      }
      geometry Box {
        size 0.2 0.1 0.05
      }
    }
    HingeJoint {
      jointParameters HingeJointParameters {
        position 229.44577174498636
        axis 0 1 0
        anchor 0.05 0.06 0
      }
      device [
        RotationalMotor {
          name "Wheel1"
        }
      ]
      endPoint Solid {
        translation 0.0500022860727387 0.06000000009977072 -3.278192067836893e-06
        rotation 0.038711200348702936 -0.7068580387014974 0.706295374535778 3.0641473023200243
        children [
          DEF Wheel Shape {
            appearance PBRAppearance {
              baseColor 0.666667 0.333333 0
              metalness 0
            }
            geometry Cylinder {
              height 0.02
              radius 0.04
            }
          }
        ]
        boundingObject USE Wheel
        physics DEF Physics_wh Physics {
        }
      }
    }
    HingeJoint {
      jointParameters HingeJointParameters {
        position 162.6971877936873
        axis 0 1 0
        anchor 0.05 -0.06 0
      }
      device [
        RotationalMotor {
          name "Wheel2"
        }
      ]
      endPoint Solid {
        translation 0.049993101724944734 -0.05999991723334277 1.0303131880018568e-05
        rotation -0.8983268747843552 0.3107753167110741 -0.3105278225269114 4.606164763390524
        children [
          USE Wheel
        ]
        name "solid(1)"
        boundingObject USE Wheel
        physics USE Physics_wh
      }
    }
    HingeJoint {
      jointParameters HingeJointParameters {
        position 230.2694364850907
        axis 0 1 0
        anchor -0.05 0.06 0
      }
      device [
        RotationalMotor {
          name "Wheel3"
        }
      ]
      endPoint Solid {
        translation -0.050007861973598265 0.06000011177327655 -8.804400229223809e-06
        rotation 0.33539238122249115 -0.6664151625939949 0.6658849612979154 2.4939075100993024
        children [
          USE Wheel
        ]
        name "solid(2)"
        boundingObject USE Wheel
        physics USE Physics_wh
      }
    }
    HingeJoint {
      jointParameters HingeJointParameters {
        position 162.8451017575794
        axis 0 1 0
        anchor -0.05 -0.06 0
      }
      device [
        RotationalMotor {
          name "Wheel4"
        }
      ]
      endPoint Solid {
        translation -0.05000119101952594 -0.05999999990128034 3.823509335997669e-06
        rotation -0.9364424748603148 0.24816677814619517 -0.24796923499100795 4.647563571984403
        children [
          USE Wheel
        ]
        name "solid(3)"
        boundingObject USE Wheel
        physics USE Physics_wh
      }
    }
    DistanceSensor {
      translation 0.1 0.02 0
      rotation 0 0 1 0.3
      children [
        DEF sensor Shape {
          appearance PBRAppearance {
            baseColor 0.333333 1 1
            metalness 0
          }
          geometry Box {
            size 0.01 0.01 0.01
          }
        }
      ]
      name "ds_left"
      boundingObject USE sensor
      physics Physics {
      }
    }
    DistanceSensor {
      translation 0.1 -0.02 0
      rotation 0 0 1 -0.27
      children [
        DEF sensor Shape {
          appearance PBRAppearance {
            baseColor 0.333333 1 1
            metalness 0
          }
          geometry Box {
            size 0.01 0.01 0.01
          }
        }
      ]
      name "ds_right"
      boundingObject USE sensor
      physics Physics {
      }
    }
    DistanceSensor {
      translation 0.085 0 -0.023
      rotation -0.004100340762836766 -0.9999831860391573 0.004100590762883277 -1.5708153071795863
      children [
        DEF colorSensor Shape {
          appearance PBRAppearance {
            baseColor 0.333333 1 1
            metalness 0
          }
          geometry Box {
            size 0.01 0.01 0.01
          }
        }
      ]
      name "colorSensor"
      boundingObject USE colorSensor
      physics Physics {
      }
      type "infra-red"
    }
  ]
  boundingObject USE Body
  physics Physics {
    density -1
    mass 1
  }
  controller "four_wheeled_collision_avoidance"
}
