#VRML_SIM R2022b utf8

EXTERNPROTO "https://raw.githubusercontent.com/cyberbotics/webots/R2022b/projects/objects/backgrounds/protos/TexturedBackground.proto"
EXTERNPROTO "https://raw.githubusercontent.com/cyberbotics/webots/R2022b/projects/objects/backgrounds/protos/TexturedBackgroundLight.proto"
EXTERNPROTO "https://raw.githubusercontent.com/cyberbotics/webots/R2022b/projects/objects/floors/protos/Floor.proto"

WorldInfo {
  contactProperties [
    ContactProperties {
      material2 "db"
      coulombFriction [
        0.5
      ]
    }
  ]
}
Viewpoint {
  orientation 0.36169761045985993 -0.31039754394196606 -0.8791064800707719 4.420782949341059
  position 0.23301416217418308 -1.0623053064502936 1.5007353268383716
}
TexturedBackground {
}
TexturedBackgroundLight {
}
Floor {
  size 5 5
  tileSize 0.25 0.25
}
DEF Tor Solid {
  translation 1.19 0.18 0
  scale 0.02 0.02 0.02
  children [
    DEF Tor Shape {
      appearance PBRAppearance {
        baseColor 0 0 0
        roughness 1
      }
      geometry Mesh {
        url [
          "../Tor3.stl"
        ]
      }
    }
  ]
  boundingObject USE Tor
}
Robot {
  translation -0.2646813979464372 -0.22063138305711477 0.03971890811496274
  rotation 0.00012419245420892302 -3.426796143044746e-05 0.9999999917009705 1.6598126196292309
  children [
    DEF Body Shape {
      appearance PBRAppearance {
        baseColor 1 1 0
        metalness 0
      }
      geometry Box {
        size 0.2 0.1 0.025
      }
    }
    HingeJoint {
      jointParameters HingeJointParameters {
        position 416.38599138974894
        axis 0 1 0
        anchor 0.05 0.06 0
      }
      device [
        RotationalMotor {
          name "Wheel1"
        }
      ]
      endPoint Solid {
        translation 0.05000331313433896 0.06000000009977072 2.2351314619391534e-06
        rotation -0.5291379126933847 -0.6002442982487907 0.5997664977058196 4.1156218023816535
        children [
          DEF Wheel Shape {
            appearance PBRAppearance {
              baseColor 0.666667 0.333333 0
              metalness 0
            }
            geometry Cylinder {
              height 0.02
              radius 0.04
            }
          }
        ]
        boundingObject USE Wheel
        physics DEF Physics_wh Physics {
        }
      }
    }
    HingeJoint {
      jointParameters HingeJointParameters {
        position 358.7919049524109
        axis 0 1 0
        anchor 0.05 -0.06 0
      }
      device [
        RotationalMotor {
          name "Wheel2"
        }
      ]
      endPoint Solid {
        translation 0.05000823153932792 -0.05999991723334277 9.272674132510857e-06
        rotation 0.9025853151867111 0.30453851870557375 -0.3042959734106257 1.6723168323369373
        children [
          USE Wheel
        ]
        name "solid(1)"
        boundingObject USE Wheel
        physics USE Physics_wh
      }
    }
    HingeJoint {
      jointParameters HingeJointParameters {
        position 417.71562801731034
        axis 0 1 0
        anchor -0.05 0.06 0
      }
      device [
        RotationalMotor {
          name "Wheel3"
        }
      ]
      endPoint Solid {
        translation -0.04999628183218748 0.06000011177327655 -1.1202826445794121e-05
        rotation -0.04107616399532491 -0.7067910998563054 0.7062287801522558 3.223764143238017
        children [
          USE Wheel
        ]
        name "solid(2)"
        boundingObject USE Wheel
        physics USE Physics_wh
      }
    }
    HingeJoint {
      jointParameters HingeJointParameters {
        position 358.9398178773908
        axis 0 1 0
        anchor -0.05 -0.06 0
      }
      device [
        RotationalMotor {
          name "Wheel4"
        }
      ]
      endPoint Solid {
        translation -0.04999660018857203 -0.05999999990128034 2.116372700613526e-06
        rotation 0.8587391403682891 0.36247494911013883 -0.36218641618251546 1.7217139126013121
        children [
          USE Wheel
        ]
        name "solid(3)"
        boundingObject USE Wheel
        physics USE Physics_wh
      }
    }
    DistanceSensor {
      translation 0.1 0.02 0
      rotation 0 0 1 0.3
      children [
        DEF sensor Shape {
          appearance PBRAppearance {
            baseColor 0.333333 1 1
            metalness 0
          }
          geometry Box {
            size 0.01 0.01 0.01
          }
        }
      ]
      name "ds_left"
      boundingObject USE sensor
      physics Physics {
      }
    }
    DistanceSensor {
      translation 0.1 -0.02 0
      rotation 0 0 1 -0.27
      children [
        DEF sensor Shape {
          appearance PBRAppearance {
            baseColor 0.333333 1 1
            metalness 0
          }
          geometry Box {
            size 0.01 0.01 0.01
          }
        }
      ]
      name "ds_right"
      boundingObject USE sensor
      physics Physics {
      }
    }
    DistanceSensor {
      translation 0.085 4.59558e-15 -0.023
      rotation -0.004100340762836766 -0.9999831860391573 0.004100590762883277 -1.5708153071795863
      children [
        DEF colorSensor Shape {
          appearance PBRAppearance {
            baseColor 0.333333 1 1
            metalness 0
          }
          geometry Box {
            size 0.01 0.01 0.01
          }
        }
      ]
      name "cs_3"
      boundingObject USE colorSensor
      physics Physics {
      }
      type "infra-red"
    }
    DistanceSensor {
      translation 0.085164 0.0199993 -0.023
      rotation -0.004100340762836766 -0.9999831860391573 0.004100590762883277 -1.5708153071795863
      children [
        DEF colorSensor Shape {
          appearance PBRAppearance {
            baseColor 0.333333 1 1
            metalness 0
          }
          geometry Box {
            size 0.01 0.01 0.01
          }
        }
      ]
      name "cs_4"
      boundingObject USE colorSensor
      physics Physics {
      }
      type "infra-red"
    }
    DistanceSensor {
      translation 0.085328 0.0399987 -0.023
      rotation -0.004100340762836766 -0.9999831860391573 0.004100590762883277 -1.5708153071795863
      children [
        DEF colorSensor Shape {
          appearance PBRAppearance {
            baseColor 0.333333 1 1
            metalness 0
          }
          geometry Box {
            size 0.01 0.01 0.01
          }
        }
      ]
      name "cs_5"
      boundingObject USE colorSensor
      physics Physics {
      }
      type "infra-red"
    }
    DistanceSensor {
      translation 0.084836 -0.0199993 -0.023
      rotation -0.004100340762836766 -0.9999831860391573 0.004100590762883277 -1.5708153071795863
      children [
        DEF colorSensor Shape {
          appearance PBRAppearance {
            baseColor 0.333333 1 1
            metalness 0
          }
          geometry Box {
            size 0.01 0.01 0.01
          }
        }
      ]
      name "cs_2"
      boundingObject USE colorSensor
      physics Physics {
      }
      type "infra-red"
    }
    DistanceSensor {
      translation 0.084672 -0.0399987 -0.023
      rotation -0.004100340762836766 -0.9999831860391573 0.004100590762883277 -1.5708153071795863
      children [
        DEF colorSensor Shape {
          appearance PBRAppearance {
            baseColor 0.333333 1 1
            metalness 0
          }
          geometry Box {
            size 0.01 0.01 0.01
          }
        }
      ]
      name "cs_1"
      boundingObject USE colorSensor
      physics Physics {
      }
      type "infra-red"
    }
  ]
  boundingObject USE Body
  physics Physics {
    density -1
    mass 1
  }
  controller "four_wheeled_collision_avoidance"
}
