#VRML_SIM R2022b utf8

EXTERNPROTO "https://raw.githubusercontent.com/cyberbotics/webots/R2022b/projects/objects/backgrounds/protos/TexturedBackground.proto"
EXTERNPROTO "https://raw.githubusercontent.com/cyberbotics/webots/R2022b/projects/objects/backgrounds/protos/TexturedBackgroundLight.proto"
EXTERNPROTO "https://raw.githubusercontent.com/cyberbotics/webots/R2022b/projects/objects/floors/protos/Floor.proto"

WorldInfo {
  contactProperties [
    ContactProperties {
      material2 "db"
      coulombFriction [
        0.5
      ]
    }
  ]
}
Viewpoint {
  orientation 0.36169761045985993 -0.31039754394196606 -0.8791064800707719 4.420782949341059
  position 0.4028598735117186 -2.0572970120729677 2.5088962487812383
}
TexturedBackground {
}
TexturedBackgroundLight {
}
Floor {
  size 3 3
  tileSize 0.25 0.25
  appearance Appearance {
    texture ImageTexture {
      url [
        "../tor2.png"
      ]
    }
    textureTransform TextureTransform {
      center 8.01 7
      scale 0.1 0.1
    }
  }
}
Robot {
  translation -0.488534 -0.224321 0.0397261
  rotation -6.434908996443845e-05 1.73736248581292e-05 0.9999999977786759 1.4517865275754607
  children [
    DEF Body Shape {
      appearance PBRAppearance {
        baseColor 1 1 0
        metalness 0
      }
      geometry Box {
        size 0.2 0.1 0.025
      }
    }
    HingeJoint {
      jointParameters HingeJointParameters {
        position 485.50798340278004
        axis 0 1 0
        anchor 0.05 0.06 0
      }
      device [
        RotationalMotor {
          name "Wheel1"
        }
      ]
      endPoint Solid {
        translation 0.05000332859640022 0.06000000009977072 2.212039286365841e-06
        rotation 0.5264681891888144 0.6014178479886213 -0.600939113299331 2.17174146915018
        children [
          DEF Wheel Shape {
            appearance PBRAppearance {
              baseColor 0.666667 0.333333 0
              metalness 0
            }
            geometry Cylinder {
              height 0.02
              radius 0.04
            }
          }
        ]
        boundingObject USE Wheel
        physics DEF Physics_wh Physics {
        }
      }
    }
    HingeJoint {
      jointParameters HingeJointParameters {
        position 423.99630548835586
        axis 0 1 0
        anchor 0.05 -0.06 0
      }
      device [
        RotationalMotor {
          name "Wheel2"
        }
      ]
      endPoint Solid {
        translation 0.05000053369761733 -0.05999991723334277 -1.238773151662766e-05
        rotation 0.04196352447857851 0.7067653015842309 -0.7062024292579904 3.0576480547093623
        children [
          USE Wheel
        ]
        name "solid(1)"
        boundingObject USE Wheel
        physics USE Physics_wh
      }
    }
    HingeJoint {
      jointParameters HingeJointParameters {
        position 486.8606998720051
        axis 0 1 0
        anchor -0.05 0.06 0
      }
      device [
        RotationalMotor {
          name "Wheel3"
        }
      ]
      endPoint Solid {
        translation -0.04999661991820974 0.06000011177327655 -1.1309427012359899e-05
        rotation 0.030455104388121698 0.7070599905251003 -0.7064974567649578 3.0806527954980645
        children [
          USE Wheel
        ]
        name "solid(2)"
        boundingObject USE Wheel
        physics USE Physics_wh
      }
    }
    HingeJoint {
      jointParameters HingeJointParameters {
        position 424.1442247640862
        axis 0 1 0
        anchor -0.05 -0.06 0
      }
      device [
        RotationalMotor {
          name "Wheel4"
        }
      ]
      endPoint Solid {
        translation -0.050000971214000614 -0.05999999990128034 -3.885163383790594e-06
        rotation -0.010325673926904934 0.7073505569954235 -0.7067874998726414 3.1622597171308273
        children [
          USE Wheel
        ]
        name "solid(3)"
        boundingObject USE Wheel
        physics USE Physics_wh
      }
    }
    DistanceSensor {
      translation 0.1 0.02 0
      rotation 0 0 1 0.3
      children [
        DEF sensor Shape {
          appearance PBRAppearance {
            baseColor 0.333333 1 1
            metalness 0
          }
          geometry Box {
            size 0.01 0.01 0.01
          }
        }
      ]
      name "ds_left"
      boundingObject USE sensor
      physics Physics {
      }
    }
    DistanceSensor {
      translation 0.1 -0.02 0
      rotation 0 0 1 -0.27
      children [
        DEF sensor Shape {
          appearance PBRAppearance {
            baseColor 0.333333 1 1
            metalness 0
          }
          geometry Box {
            size 0.01 0.01 0.01
          }
        }
      ]
      name "ds_right"
      boundingObject USE sensor
      physics Physics {
      }
    }
    DistanceSensor {
      translation 0.085 4.59558e-15 -0.023
      rotation -0.004100340762836766 -0.9999831860391573 0.004100590762883277 -1.5708153071795863
      children [
        DEF colorSensor Shape {
          appearance PBRAppearance {
            baseColor 0.333333 1 1
            metalness 0
          }
          geometry Box {
            size 0.01 0.01 0.01
          }
        }
      ]
      name "cs_3"
      boundingObject USE colorSensor
      physics Physics {
      }
      type "infra-red"
    }
    DistanceSensor {
      translation 0.085164 0.0199993 -0.023
      rotation -0.004100340762836766 -0.9999831860391573 0.004100590762883277 -1.5708153071795863
      children [
        DEF colorSensor Shape {
          appearance PBRAppearance {
            baseColor 0.333333 1 1
            metalness 0
          }
          geometry Box {
            size 0.01 0.01 0.01
          }
        }
      ]
      name "cs_4"
      boundingObject USE colorSensor
      physics Physics {
      }
      type "infra-red"
    }
    DistanceSensor {
      translation 0.085328 0.0399987 -0.023
      rotation -0.004100340762836766 -0.9999831860391573 0.004100590762883277 -1.5708153071795863
      children [
        DEF colorSensor Shape {
          appearance PBRAppearance {
            baseColor 0.333333 1 1
            metalness 0
          }
          geometry Box {
            size 0.01 0.01 0.01
          }
        }
      ]
      name "cs_5"
      boundingObject USE colorSensor
      physics Physics {
      }
      type "infra-red"
    }
    DistanceSensor {
      translation 0.084836 -0.0199993 -0.023
      rotation -0.004100340762836766 -0.9999831860391573 0.004100590762883277 -1.5708153071795863
      children [
        DEF colorSensor Shape {
          appearance PBRAppearance {
            baseColor 0.333333 1 1
            metalness 0
          }
          geometry Box {
            size 0.01 0.01 0.01
          }
        }
      ]
      name "cs_2"
      boundingObject USE colorSensor
      physics Physics {
      }
      type "infra-red"
    }
    DistanceSensor {
      translation 0.084672 -0.0399987 -0.023
      rotation -0.004100340762836766 -0.9999831860391573 0.004100590762883277 -1.5708153071795863
      children [
        DEF colorSensor Shape {
          appearance PBRAppearance {
            baseColor 0.333333 1 1
            metalness 0
          }
          geometry Box {
            size 0.01 0.01 0.01
          }
        }
      ]
      name "cs_1"
      boundingObject USE colorSensor
      physics Physics {
      }
      type "infra-red"
    }
  ]
  boundingObject USE Body
  physics Physics {
    density -1
    mass 1
  }
  controller "lineFollower"
}
